
2020-02-10 16:07:16,664 INFO: errors [in C:\Users\hp\Documents\Projects\01_fyyur\app.py:468]
2020-02-10 16:07:33,037 INFO: errors [in C:\Users\hp\Documents\Projects\01_fyyur\app.py:468]
2020-02-10 16:59:07,310 INFO: errors [in C:\Users\hp\Documents\Projects\01_fyyur\app.py:466]
2020-02-10 16:59:40,327 INFO: errors [in C:\Users\hp\Documents\Projects\01_fyyur\app.py:466]
2020-02-10 16:59:44,629 INFO: errors [in C:\Users\hp\Documents\Projects\01_fyyur\app.py:466]
2020-02-10 17:03:13,596 INFO: errors [in C:\Users\hp\Documents\Projects\01_fyyur\app.py:466]
2020-02-10 21:13:58,549 INFO: errors [in C:\Users\hp\Documents\Projects\01_fyyur\app.py:528]
2020-02-10 21:14:42,488 INFO: errors [in C:\Users\hp\Documents\Projects\01_fyyur\app.py:528]
2020-02-10 21:15:24,190 INFO: errors [in C:\Users\hp\Documents\Projects\01_fyyur\app.py:528]
2020-02-10 21:15:25,631 INFO: errors [in C:\Users\hp\Documents\Projects\01_fyyur\app.py:528]
2020-02-10 21:16:23,388 ERROR: Exception on /venues/create [GET] [in c:\users\hp\appdata\local\programs\python\python37\lib\site-packages\flask\app.py:1761]
Traceback (most recent call last):
  File "c:\users\hp\appdata\local\programs\python\python37\lib\site-packages\flask\app.py", line 2292, in wsgi_app
    response = self.full_dispatch_request()
  File "c:\users\hp\appdata\local\programs\python\python37\lib\site-packages\flask\app.py", line 1815, in full_dispatch_request
    rv = self.handle_user_exception(e)
  File "c:\users\hp\appdata\local\programs\python\python37\lib\site-packages\flask\app.py", line 1718, in handle_user_exception
    reraise(exc_type, exc_value, tb)
  File "c:\users\hp\appdata\local\programs\python\python37\lib\site-packages\flask\_compat.py", line 35, in reraise
    raise value
  File "c:\users\hp\appdata\local\programs\python\python37\lib\site-packages\flask\app.py", line 1813, in full_dispatch_request
    rv = self.dispatch_request()
  File "c:\users\hp\appdata\local\programs\python\python37\lib\site-packages\flask\app.py", line 1799, in dispatch_request
    return self.view_functions[rule.endpoint](**req.view_args)
  File "C:\Users\hp\Documents\Projects\01_fyyur\app.py", line 223, in create_venue_form
    form = VenueForm()
  File "c:\users\hp\appdata\local\programs\python\python37\lib\site-packages\wtforms\form.py", line 212, in __call__
    return type.__call__(cls, *args, **kwargs)
  File "c:\users\hp\appdata\local\programs\python\python37\lib\site-packages\flask_wtf\form.py", line 158, in __init__
    super(Form, self).__init__(*args, **kwargs)
  File "c:\users\hp\appdata\local\programs\python\python37\lib\site-packages\flask_wtf\form.py", line 88, in __init__
    super(FlaskForm, self).__init__(formdata=formdata, **kwargs)
  File "c:\users\hp\appdata\local\programs\python\python37\lib\site-packages\wtforms\form.py", line 278, in __init__
    self.process(formdata, obj, data=data, **kwargs)
  File "c:\users\hp\appdata\local\programs\python\python37\lib\site-packages\wtforms\form.py", line 132, in process
    field.process(formdata)
  File "c:\users\hp\appdata\local\programs\python\python37\lib\site-packages\wtforms\csrf\core.py", line 43, in process
    self.current_token = self.csrf_impl.generate_csrf_token(self)
  File "c:\users\hp\appdata\local\programs\python\python37\lib\site-packages\flask_wtf\csrf.py", line 134, in generate_csrf_token
    token_key=self.meta.csrf_field_name
  File "c:\users\hp\appdata\local\programs\python\python37\lib\site-packages\flask_wtf\csrf.py", line 35, in generate_csrf
    message='A secret key is required to use CSRF.'
  File "c:\users\hp\appdata\local\programs\python\python37\lib\site-packages\flask_wtf\csrf.py", line 121, in _get_config
    raise KeyError(message)
KeyError: 'A secret key is required to use CSRF.'
2020-02-10 21:19:52,104 INFO: errors [in C:\Users\hp\Documents\Projects\01_fyyur\app.py:528]
2020-02-10 21:19:59,047 INFO: errors [in C:\Users\hp\Documents\Projects\01_fyyur\app.py:528]
2020-02-10 21:24:58,539 INFO: errors [in C:\Users\hp\Documents\Projects\01_fyyur\app.py:528]
2020-02-10 21:25:08,518 INFO: errors [in C:\Users\hp\Documents\Projects\01_fyyur\app.py:528]
2020-02-10 21:25:21,799 INFO: errors [in C:\Users\hp\Documents\Projects\01_fyyur\app.py:528]
2020-02-10 21:28:16,381 ERROR: Exception on /venues [GET] [in c:\users\hp\appdata\local\programs\python\python37\lib\site-packages\flask\app.py:1761]
Traceback (most recent call last):
  File "c:\users\hp\appdata\local\programs\python\python37\lib\site-packages\flask\app.py", line 2292, in wsgi_app
    response = self.full_dispatch_request()
  File "c:\users\hp\appdata\local\programs\python\python37\lib\site-packages\flask\app.py", line 1815, in full_dispatch_request
    rv = self.handle_user_exception(e)
  File "c:\users\hp\appdata\local\programs\python\python37\lib\site-packages\flask\app.py", line 1718, in handle_user_exception
    reraise(exc_type, exc_value, tb)
  File "c:\users\hp\appdata\local\programs\python\python37\lib\site-packages\flask\_compat.py", line 35, in reraise
    raise value
  File "c:\users\hp\appdata\local\programs\python\python37\lib\site-packages\flask\app.py", line 1813, in full_dispatch_request
    rv = self.dispatch_request()
  File "c:\users\hp\appdata\local\programs\python\python37\lib\site-packages\flask\app.py", line 1799, in dispatch_request
    return self.view_functions[rule.endpoint](**req.view_args)
  File "C:\Users\hp\Documents\Projects\01_fyyur\app.py", line 138, in venues
    if show.start_time > datetime.now(pytz.utc):
TypeError: can't compare offset-naive and offset-aware datetimes
2020-02-10 21:34:23,084 ERROR: Exception on /venues [GET] [in c:\users\hp\appdata\local\programs\python\python37\lib\site-packages\flask\app.py:1761]
Traceback (most recent call last):
  File "c:\users\hp\appdata\local\programs\python\python37\lib\site-packages\flask\app.py", line 2292, in wsgi_app
    response = self.full_dispatch_request()
  File "c:\users\hp\appdata\local\programs\python\python37\lib\site-packages\flask\app.py", line 1815, in full_dispatch_request
    rv = self.handle_user_exception(e)
  File "c:\users\hp\appdata\local\programs\python\python37\lib\site-packages\flask\app.py", line 1718, in handle_user_exception
    reraise(exc_type, exc_value, tb)
  File "c:\users\hp\appdata\local\programs\python\python37\lib\site-packages\flask\_compat.py", line 35, in reraise
    raise value
  File "c:\users\hp\appdata\local\programs\python\python37\lib\site-packages\flask\app.py", line 1813, in full_dispatch_request
    rv = self.dispatch_request()
  File "c:\users\hp\appdata\local\programs\python\python37\lib\site-packages\flask\app.py", line 1799, in dispatch_request
    return self.view_functions[rule.endpoint](**req.view_args)
  File "C:\Users\hp\Documents\Projects\01_fyyur\app.py", line 138, in venues
    if show.start_time > datetime.now(pytz.utc):
TypeError: can't compare offset-naive and offset-aware datetimes
2020-02-10 21:36:49,140 INFO: errors [in C:\Users\hp\Documents\Projects\01_fyyur\app.py:528]
2020-02-10 21:37:05,770 ERROR: Exception on /venues/1 [GET] [in c:\users\hp\appdata\local\programs\python\python37\lib\site-packages\flask\app.py:1761]
Traceback (most recent call last):
  File "c:\users\hp\appdata\local\programs\python\python37\lib\site-packages\flask\app.py", line 2292, in wsgi_app
    response = self.full_dispatch_request()
  File "c:\users\hp\appdata\local\programs\python\python37\lib\site-packages\flask\app.py", line 1815, in full_dispatch_request
    rv = self.handle_user_exception(e)
  File "c:\users\hp\appdata\local\programs\python\python37\lib\site-packages\flask\app.py", line 1718, in handle_user_exception
    reraise(exc_type, exc_value, tb)
  File "c:\users\hp\appdata\local\programs\python\python37\lib\site-packages\flask\_compat.py", line 35, in reraise
    raise value
  File "c:\users\hp\appdata\local\programs\python\python37\lib\site-packages\flask\app.py", line 1813, in full_dispatch_request
    rv = self.dispatch_request()
  File "c:\users\hp\appdata\local\programs\python\python37\lib\site-packages\flask\app.py", line 1799, in dispatch_request
    return self.view_functions[rule.endpoint](**req.view_args)
  File "C:\Users\hp\Documents\Projects\01_fyyur\app.py", line 190, in show_venue
    if show.start_time > datetime.now(pytz.utc):
TypeError: can't compare offset-naive and offset-aware datetimes
2020-02-10 21:37:56,390 INFO: errors [in C:\Users\hp\Documents\Projects\01_fyyur\app.py:528]
2020-02-10 21:38:00,149 ERROR: Exception on /venues/1 [GET] [in c:\users\hp\appdata\local\programs\python\python37\lib\site-packages\flask\app.py:1761]
Traceback (most recent call last):
  File "c:\users\hp\appdata\local\programs\python\python37\lib\site-packages\flask\app.py", line 2292, in wsgi_app
    response = self.full_dispatch_request()
  File "c:\users\hp\appdata\local\programs\python\python37\lib\site-packages\flask\app.py", line 1815, in full_dispatch_request
    rv = self.handle_user_exception(e)
  File "c:\users\hp\appdata\local\programs\python\python37\lib\site-packages\flask\app.py", line 1718, in handle_user_exception
    reraise(exc_type, exc_value, tb)
  File "c:\users\hp\appdata\local\programs\python\python37\lib\site-packages\flask\_compat.py", line 35, in reraise
    raise value
  File "c:\users\hp\appdata\local\programs\python\python37\lib\site-packages\flask\app.py", line 1813, in full_dispatch_request
    rv = self.dispatch_request()
  File "c:\users\hp\appdata\local\programs\python\python37\lib\site-packages\flask\app.py", line 1799, in dispatch_request
    return self.view_functions[rule.endpoint](**req.view_args)
  File "C:\Users\hp\Documents\Projects\01_fyyur\app.py", line 190, in show_venue
    if show.start_time > datetime.now(pytz.utc):
TypeError: can't compare offset-naive and offset-aware datetimes
2020-02-10 21:38:15,488 INFO: errors [in C:\Users\hp\Documents\Projects\01_fyyur\app.py:528]
2020-02-10 21:38:18,046 INFO: errors [in C:\Users\hp\Documents\Projects\01_fyyur\app.py:528]
2020-02-10 21:38:18,621 ERROR: Exception on /venues/1 [GET] [in c:\users\hp\appdata\local\programs\python\python37\lib\site-packages\flask\app.py:1761]
Traceback (most recent call last):
  File "c:\users\hp\appdata\local\programs\python\python37\lib\site-packages\flask\app.py", line 2292, in wsgi_app
    response = self.full_dispatch_request()
  File "c:\users\hp\appdata\local\programs\python\python37\lib\site-packages\flask\app.py", line 1815, in full_dispatch_request
    rv = self.handle_user_exception(e)
  File "c:\users\hp\appdata\local\programs\python\python37\lib\site-packages\flask\app.py", line 1718, in handle_user_exception
    reraise(exc_type, exc_value, tb)
  File "c:\users\hp\appdata\local\programs\python\python37\lib\site-packages\flask\_compat.py", line 35, in reraise
    raise value
  File "c:\users\hp\appdata\local\programs\python\python37\lib\site-packages\flask\app.py", line 1813, in full_dispatch_request
    rv = self.dispatch_request()
  File "c:\users\hp\appdata\local\programs\python\python37\lib\site-packages\flask\app.py", line 1799, in dispatch_request
    return self.view_functions[rule.endpoint](**req.view_args)
  File "C:\Users\hp\Documents\Projects\01_fyyur\app.py", line 190, in show_venue
    if show.start_time > datetime.now(pytz.utc):
TypeError: can't compare offset-naive and offset-aware datetimes
2020-02-10 21:38:39,169 INFO: errors [in C:\Users\hp\Documents\Projects\01_fyyur\app.py:528]
